Workbook

Sheet System_configuration
C1: =IF(E5=1, "Tragen Sie die Produktbezeichnungen Ihrer Module in die Spalte „Produkt“ ein um eine Auswertung zu erhalten. Die verfügbaren Produkte und deren technischen Angaben stehen in der Tabelle 'Data_source' und können dort erweitert werden.", "Enter the product names of your modules in the column “Product” in order to obtain an evaluation. The available products and their specifications are in the table 'Data_source' and can be extended there.") -> Enter the product names of your modules in the column “Product” in order to obtain an evaluation. The available products and their specifications are in the table 'Data_source' and can be extended there.
C2: =IF(E5=1, "Sollten sich technische Daten der Produkte ändern, können diese in der Tabelle 'Data_source' angepasst werden. !!!! Die Konfiguration muss immer noch einmal durch den Bediener auf Richtigkeit geprüft werden !!!!", "Should specifications of the products change, they can be adjusted in the table 'Data_source'. !!!! The configuration must be always checked for correctness by the operator !!!!") -> Should specifications of the products change, they can be adjusted in the table 'Data_source'. !!!! The configuration must be always checked for correctness by the operator !!!!
F4: Deutsch | J4: -T- | K4: =IF(E5=1, "Busbeginn mit Potenzialeinspeisung", "Bus start with potential supply") -> Bus start with potential supply
A5: Sprache / Language: | E5: 2 | F5: English | J5: T | K5: =IF(E5=1, "Potenzialeinspeisung", "Potential supply") -> Potential supply
E6: =IF(E5=1, "Farbe blau: Eingaben veränderbar", "Color blue: Inputs changeable") -> Color blue: Inputs changeable | J6: | | K6: =IF(E5=1, "Potenzialweiterleitung", "Potential forwarding") -> Potential forwarding
A7: =IF(E5=1, "Projekt:", "Project:") -> Project: | C7: Demo-Rack mobile IoT V1.0 | E7: =IF(E5=1, "Farbe grau: Reststrom oder Gesamtbreite", "Color gray: Residual current or overall width") -> Color gray: Residual current or overall width | K7: =IF(E5=1, "Potenzialtrennung", "Potential separation") -> Potential separation
E8: =IF(E5=1, "Farbe rot: Fehler in der Konfiguration", "Color red: Configuration error") -> Color red: Configuration error | J8: === | K8: =IF(E5=1, "Potenzialtrennung und Klemmen mit Potenzialweiterleitung dürfen nachfolgend nicht verwendet werden!", "Potential separation and terminals with potential forwarding may not be used below!") -> Potential separation and terminals with potential forwarding may not be used below!
J9: --- | K9: =IF(E6=1, "Busabschluss", "Bus termination") -> Bus termination
A10: Nr | B10: =IF(E5=1, "Produkt", "Product") -> Product | C10: =IF(E5=1, "Produkt Beschreibung", "Product Description") -> Product Description | D10: =IF(E5=1, "E-Bus Strom (mA)", "E-Bus current (mA)") -> E-Bus current (mA) | E10: =IF(E5=1, "E-Bus Reststrom (mA)", "E-Bus residual current (mA)") -> E-Bus residual current (mA) | F10: =IF(E5=1, "K-Bus Strom (mA)", "K-Bus current (mA)") -> K-Bus current (mA) | G10: =IF(E5=1, "K-Bus Reststrom (mA)", "K-Bus residual current (mA)") -> K-Bus residual current (mA) | H10: =IF(E5=1, "Produkt Breite (mm)", "Product width (mm)") -> Product width (mm) | I10: =IF(E5=1, "Gesamtbreite (mm)", "Overall width (mm)") -> Overall width (mm) | J10: =IF(System_configuration!E5=1, "Power Kontakt","Power contact") -> Power contact | M10: =IF(E5=1, "Kommentar", "Comment") -> Comment
J11: + | K11: - | L11: PE
A12: 1 | B12: EK1100 | C12: =IF($E$5=1,IF(ISBLANK(B12)=FALSE,VLOOKUP(B12,Data_source!A:J,4,FALSE),""),IF(ISBLANK(B12)=FALSE,VLOOKUP(B12,Data_source!A:J,5,FALSE),"")) -> EtherCAT Coupler for E-bus terminals (ELxxxx) | D12: =IF(ISBLANK(B12)=FALSE,IF(VLOOKUP(B12,Data_source!A:J,2,FALSE)="---","",VLOOKUP(B12,Data_source!A:J,2,FALSE)),"") -> 2000 | E12: =D12 -> 2000 | F12: =IF(ISBLANK(B12)=FALSE,IF(VLOOKUP(B12,Data_source!A:J,3,FALSE)="---","",VLOOKUP(B12,Data_source!A:J,3,FALSE)),"") | G12: =F12 | H12: =IF(ISBLANK(B12)=FALSE,IF(VLOOKUP(B12,Data_source!A:J,6,FALSE)="---","",VLOOKUP(B12,Data_source!A:J,6,FALSE)),"") -> 44 | I12: =H12 -> 44 | J12: =IF(ISBLANK(B12)=FALSE,IF(VLOOKUP(B12,Data_source!A:J,7,FALSE)=0,"",VLOOKUP(B12,Data_source!A:J,7,FALSE)),"") -> -T- | K12: =IF(ISBLANK(B12)=FALSE,IF(VLOOKUP(B12,Data_source!A:J,8,FALSE)=0,"",VLOOKUP(B12,Data_source!A:J,8,FALSE)),"") -> -T- | L12: =IF(ISBLANK(B12)=FALSE,IF(VLOOKUP(B12,Data_source!A:J,9,FALSE)=0,"",VLOOKUP(B12,Data_source!A:J,9,FALSE)),"") -> -T-
A13: 2 | B13: EL1859 | C13: =IF($E$5=1,IF(ISBLANK(B13)=FALSE,VLOOKUP(B13,Data_source!A:J,4,FALSE),""),IF(ISBLANK(B13)=FALSE,VLOOKUP(B13,Data_source!A:J,5,FALSE),"")) -> 8-channel digital input terminal 24 V DC, filter 3.0 ms, type 3, + 8-channel digital output terminal 24 V DC, 0.5 A, 1-wire system | D13: =IF(ISBLANK(B13)=FALSE,IF(VLOOKUP(B13,Data_source!A:J,2,FALSE)="---","",VLOOKUP(B13,Data_source!A:J,2,FALSE)),"") -> -130 | E13: =IF(F13<>"",D13,IF(D13>0,D13,IF(E12="",D13,E12+D13))) -> 1870 | F13: =IF(ISBLANK(B13)=FALSE,IF(VLOOKUP(B13,Data_source!A:J,3,FALSE)="---","",VLOOKUP(B13,Data_source!A:J,3,FALSE)),"") | G13: =IF(F13>0, F13, IF(F13="", "", IF(G12="", F13, G12+F13))) | H13: =IF(ISBLANK(B13)=FALSE,IF(VLOOKUP(B13,Data_source!A:J,6,FALSE)="---","",VLOOKUP(B13,Data_source!A:J,6,FALSE)),"") -> 12 | I13: =IF(H13="","",IF(H12="",H13,H13+I12)) -> 56 | J13: =IF(ISBLANK(B13)=FALSE,IF(VLOOKUP(B13,Data_source!A:J,7,FALSE)=0,"",VLOOKUP(B13,Data_source!A:J,7,FALSE)),"") -> | | K13: =IF(ISBLANK(B13)=FALSE,IF(VLOOKUP(B13,Data_source!A:J,8,FALSE)=0,"",VLOOKUP(B13,Data_source!A:J,8,FALSE)),"") -> | | L13: =IF(ISBLANK(B13)=FALSE,IF(VLOOKUP(B13,Data_source!A:J,9,FALSE)=0,"",VLOOKUP(B13,Data_source!A:J,9,FALSE)),"")
A14: 3 | B14: EL1859 | C14: =IF($E$5=1,IF(ISBLANK(B14)=FALSE,VLOOKUP(B14,Data_source!A:J,4,FALSE),""),IF(ISBLANK(B14)=FALSE,VLOOKUP(B14,Data_source!A:J,5,FALSE),"")) -> 8-channel digital input terminal 24 V DC, filter 3.0 ms, type 3, + 8-channel digital output terminal 24 V DC, 0.5 A, 1-wire system | D14: =IF(ISBLANK(B14)=FALSE,IF(VLOOKUP(B14,Data_source!A:J,2,FALSE)="---","",VLOOKUP(B14,Data_source!A:J,2,FALSE)),"") -> -130 | E14: =IF(F14<>"",D14,IF(D14>0,D14,IF(E13="",D14,E13+D14))) -> 1740 | F14: =IF(ISBLANK(B14)=FALSE,IF(VLOOKUP(B14,Data_source!A:J,3,FALSE)="---","",VLOOKUP(B14,Data_source!A:J,3,FALSE)),"") | G14: =IF(F14>0, F14, IF(F14="", "", IF(G13="", F14, G13+F14))) | H14: =IF(ISBLANK(B14)=FALSE,IF(VLOOKUP(B14,Data_source!A:J,6,FALSE)="---","",VLOOKUP(B14,Data_source!A:J,6,FALSE)),"") -> 12 | I14: =IF(H14="","",IF(H13="",H14,H14+I13)) -> 68 | J14: =IF(ISBLANK(B14)=FALSE,IF(VLOOKUP(B14,Data_source!A:J,7,FALSE)=0,"",VLOOKUP(B14,Data_source!A:J,7,FALSE)),"") -> | | K14: =IF(ISBLANK(B14)=FALSE,IF(VLOOKUP(B14,Data_source!A:J,8,FALSE)=0,"",VLOOKUP(B14,Data_source!A:J,8,FALSE)),"") -> | | L14: =IF(ISBLANK(B14)=FALSE,IF(VLOOKUP(B14,Data_source!A:J,9,FALSE)=0,"",VLOOKUP(B14,Data_source!A:J,9,FALSE)),"")
A15: 4 | B15: EL1004 | C15: =IF($E$5=1,IF(ISBLANK(B15)=FALSE,VLOOKUP(B15,Data_source!A:J,4,FALSE),""),IF(ISBLANK(B15)=FALSE,VLOOKUP(B15,Data_source!A:J,5,FALSE),"")) -> 4-channel digital input terminal 24 V DC, filter 3.0 ms, 2-wire system | D15: =IF(ISBLANK(B15)=FALSE,IF(VLOOKUP(B15,Data_source!A:J,2,FALSE)="---","",VLOOKUP(B15,Data_source!A:J,2,FALSE)),"") -> -90 | E15: =IF(F15<>"",D15,IF(D15>0,D15,IF(E14="",D15,E14+D15))) -> 1650 | F15: =IF(ISBLANK(B15)=FALSE,IF(VLOOKUP(B15,Data_source!A:J,3,FALSE)="---","",VLOOKUP(B15,Data_source!A:J,3,FALSE)),"") | G15: =IF(F15>0, F15, IF(F15="", "", IF(G14="", F15, G14+F15))) | H15: =IF(ISBLANK(B15)=FALSE,IF(VLOOKUP(B15,Data_source!A:J,6,FALSE)="---","",VLOOKUP(B15,Data_source!A:J,6,FALSE)),"") -> 12 | I15: =IF(H15="","",IF(H14="",H15,H15+I14)) -> 80 | J15: =IF(ISBLANK(B15)=FALSE,IF(VLOOKUP(B15,Data_source!A:J,7,FALSE)=0,"",VLOOKUP(B15,Data_source!A:J,7,FALSE)),"") -> | | K15: =IF(ISBLANK(B15)=FALSE,IF(VLOOKUP(B15,Data_source!A:J,8,FALSE)=0,"",VLOOKUP(B15,Data_source!A:J,8,FALSE)),"") -> | | L15: =IF(ISBLANK(B15)=FALSE,IF(VLOOKUP(B15,Data_source!A:J,9,FALSE)=0,"",VLOOKUP(B15,Data_source!A:J,9,FALSE)),"")
A16: 5 | B16: EL2034 | C16: =IF($E$5=1,IF(ISBLANK(B16)=FALSE,VLOOKUP(B16,Data_source!A:J,4,FALSE),""),IF(ISBLANK(B16)=FALSE,VLOOKUP(B16,Data_source!A:J,5,FALSE),"")) -> 4-channel digital output terminal 24 V DC, 2 A, with diagnostics, 2-wire system | D16: =IF(ISBLANK(B16)=FALSE,IF(VLOOKUP(B16,Data_source!A:J,2,FALSE)="---","",VLOOKUP(B16,Data_source!A:J,2,FALSE)),"") -> -120 | E16: =IF(F16<>"",D16,IF(D16>0,D16,IF(E15="",D16,E15+D16))) -> 1530 | F16: =IF(ISBLANK(B16)=FALSE,IF(VLOOKUP(B16,Data_source!A:J,3,FALSE)="---","",VLOOKUP(B16,Data_source!A:J,3,FALSE)),"") | G16: =IF(F16>0, F16, IF(F16="", "", IF(G15="", F16, G15+F16))) | H16: =IF(ISBLANK(B16)=FALSE,IF(VLOOKUP(B16,Data_source!A:J,6,FALSE)="---","",VLOOKUP(B16,Data_source!A:J,6,FALSE)),"") -> 12 | I16: =IF(H16="","",IF(H15="",H16,H16+I15)) -> 92 | J16: =IF(ISBLANK(B16)=FALSE,IF(VLOOKUP(B16,Data_source!A:J,7,FALSE)=0,"",VLOOKUP(B16,Data_source!A:J,7,FALSE)),"") -> | | K16: =IF(ISBLANK(B16)=FALSE,IF(VLOOKUP(B16,Data_source!A:J,8,FALSE)=0,"",VLOOKUP(B16,Data_source!A:J,8,FALSE)),"") -> | | L16: =IF(ISBLANK(B16)=FALSE,IF(VLOOKUP(B16,Data_source!A:J,9,FALSE)=0,"",VLOOKUP(B16,Data_source!A:J,9,FALSE)),"")
A17: 6 | B17: EL3255 | C17: =IF($E$5=1,IF(ISBLANK(B17)=FALSE,VLOOKUP(B17,Data_source!A:J,4,FALSE),""),IF(ISBLANK(B17)=FALSE,VLOOKUP(B17,Data_source!A:J,5,FALSE),"")) -> 5-channel analog input terminal, potentiometer measurement with 10 V sensor supply, 3-wire system | D17: =IF(ISBLANK(B17)=FALSE,IF(VLOOKUP(B17,Data_source!A:J,2,FALSE)="---","",VLOOKUP(B17,Data_source!A:J,2,FALSE)),"") -> -80 | E17: =IF(F17<>"",D17,IF(D17>0,D17,IF(E16="",D17,E16+D17))) -> 1450 | F17: =IF(ISBLANK(B17)=FALSE,IF(VLOOKUP(B17,Data_source!A:J,3,FALSE)="---","",VLOOKUP(B17,Data_source!A:J,3,FALSE)),"") | G17: =IF(F17>0, F17, IF(F17="", "", IF(G16="", F17, G16+F17))) | H17: =IF(ISBLANK(B17)=FALSE,IF(VLOOKUP(B17,Data_source!A:J,6,FALSE)="---","",VLOOKUP(B17,Data_source!A:J,6,FALSE)),"") -> 12 | I17: =IF(H17="","",IF(H16="",H17,H17+I16)) -> 104 | J17: =IF(ISBLANK(B17)=FALSE,IF(VLOOKUP(B17,Data_source!A:J,7,FALSE)=0,"",VLOOKUP(B17,Data_source!A:J,7,FALSE)),"") -> | | K17: =IF(ISBLANK(B17)=FALSE,IF(VLOOKUP(B17,Data_source!A:J,8,FALSE)=0,"",VLOOKUP(B17,Data_source!A:J,8,FALSE)),"") -> | | L17: =IF(ISBLANK(B17)=FALSE,IF(VLOOKUP(B17,Data_source!A:J,9,FALSE)=0,"",VLOOKUP(B17,Data_source!A:J,9,FALSE)),"")
A18: 7 | B18: EL5151 | C18: =IF($E$5=1,IF(ISBLANK(B18)=FALSE,VLOOKUP(B18,Data_source!A:J,4,FALSE),""),IF(ISBLANK(B18)=FALSE,VLOOKUP(B18,Data_source!A:J,5,FALSE),"")) -> 1-channel incremental encoder interface, 32 bit | D18: =IF(ISBLANK(B18)=FALSE,IF(VLOOKUP(B18,Data_source!A:J,2,FALSE)="---","",VLOOKUP(B18,Data_source!A:J,2,FALSE)),"") -> -130 | E18: =IF(F18<>"",D18,IF(D18>0,D18,IF(E17="",D18,E17+D18))) -> 1320 | F18: =IF(ISBLANK(B18)=FALSE,IF(VLOOKUP(B18,Data_source!A:J,3,FALSE)="---","",VLOOKUP(B18,Data_source!A:J,3,FALSE)),"") | G18: =IF(F18>0, F18, IF(F18="", "", IF(G17="", F18, G17+F18))) | H18: =IF(ISBLANK(B18)=FALSE,IF(VLOOKUP(B18,Data_source!A:J,6,FALSE)="---","",VLOOKUP(B18,Data_source!A:J,6,FALSE)),"") -> 12 | I18: =IF(H18="","",IF(H17="",H18,H18+I17)) -> 116 | J18: =IF(ISBLANK(B18)=FALSE,IF(VLOOKUP(B18,Data_source!A:J,7,FALSE)=0,"",VLOOKUP(B18,Data_source!A:J,7,FALSE)),"") -> | | K18: =IF(ISBLANK(B18)=FALSE,IF(VLOOKUP(B18,Data_source!A:J,8,FALSE)=0,"",VLOOKUP(B18,Data_source!A:J,8,FALSE)),"") -> | | L18: =IF(ISBLANK(B18)=FALSE,IF(VLOOKUP(B18,Data_source!A:J,9,FALSE)=0,"",VLOOKUP(B18,Data_source!A:J,9,FALSE)),"")
A19: 8 | B19: EL3318 | C19: =IF($E$5=1,IF(ISBLANK(B19)=FALSE,VLOOKUP(B19,Data_source!A:J,4,FALSE),""),IF(ISBLANK(B19)=FALSE,VLOOKUP(B19,Data_source!A:J,5,FALSE),"")) -> 8-channel thermocouple input terminal, preset to type K, with wire breakage detection, 16 bit | D19: =IF(ISBLANK(B19)=FALSE,IF(VLOOKUP(B19,Data_source!A:J,2,FALSE)="---","",VLOOKUP(B19,Data_source!A:J,2,FALSE)),"") -> -210 | E19: =IF(F19<>"",D19,IF(D19>0,D19,IF(E18="",D19,E18+D19))) -> 1110 | F19: =IF(ISBLANK(B19)=FALSE,IF(VLOOKUP(B19,Data_source!A:J,3,FALSE)="---","",VLOOKUP(B19,Data_source!A:J,3,FALSE)),"") | G19: =IF(F19>0, F19, IF(F19="", "", IF(G18="", F19, G18+F19))) | H19: =IF(ISBLANK(B19)=FALSE,IF(VLOOKUP(B19,Data_source!A:J,6,FALSE)="---","",VLOOKUP(B19,Data_source!A:J,6,FALSE)),"") -> 12 | I19: =IF(H19="","",IF(H18="",H19,H19+I18)) -> 128 | J19: =IF(ISBLANK(B19)=FALSE,IF(VLOOKUP(B19,Data_source!A:J,7,FALSE)=0,"",VLOOKUP(B19,Data_source!A:J,7,FALSE)),"") -> | | K19: =IF(ISBLANK(B19)=FALSE,IF(VLOOKUP(B19,Data_source!A:J,8,FALSE)=0,"",VLOOKUP(B19,Data_source!A:J,8,FALSE)),"") -> | | L19: =IF(ISBLANK(B19)=FALSE,IF(VLOOKUP(B19,Data_source!A:J,9,FALSE)=0,"",VLOOKUP(B19,Data_source!A:J,9,FALSE)),"")
A20: 9 | B20: EL7332 | C20: =IF($E$5=1,IF(ISBLANK(B20)=FALSE,VLOOKUP(B20,Data_source!A:J,4,FALSE),""),IF(ISBLANK(B20)=FALSE,VLOOKUP(B20,Data_source!A:J,5,FALSE),"")) -> 2-channel DC motor output stage 24 V DC, 1 A | D20: =IF(ISBLANK(B20)=FALSE,IF(VLOOKUP(B20,Data_source!A:J,2,FALSE)="---","",VLOOKUP(B20,Data_source!A:J,2,FALSE)),"") -> -140 | E20: =IF(F20<>"",D20,IF(D20>0,D20,IF(E19="",D20,E19+D20))) -> 970 | F20: =IF(ISBLANK(B20)=FALSE,IF(VLOOKUP(B20,Data_source!A:J,3,FALSE)="---","",VLOOKUP(B20,Data_source!A:J,3,FALSE)),"") | G20: =IF(F20>0, F20, IF(F20="", "", IF(G19="", F20, G19+F20))) | H20: =IF(ISBLANK(B20)=FALSE,IF(VLOOKUP(B20,Data_source!A:J,6,FALSE)="---","",VLOOKUP(B20,Data_source!A:J,6,FALSE)),"") -> 12 | I20: =IF(H20="","",IF(H19="",H20,H20+I19)) -> 140 | J20: =IF(ISBLANK(B20)=FALSE,IF(VLOOKUP(B20,Data_source!A:J,7,FALSE)=0,"",VLOOKUP(B20,Data_source!A:J,7,FALSE)),"") -> | | K20: =IF(ISBLANK(B20)=FALSE,IF(VLOOKUP(B20,Data_source!A:J,8,FALSE)=0,"",VLOOKUP(B20,Data_source!A:J,8,FALSE)),"") -> | | L20: =IF(ISBLANK(B20)=FALSE,IF(VLOOKUP(B20,Data_source!A:J,9,FALSE)=0,"",VLOOKUP(B20,Data_source!A:J,9,FALSE)),"")
A21: 10 | B21: EL3443 | C21: =IF($E$5=1,IF(ISBLANK(B21)=FALSE,VLOOKUP(B21,Data_source!A:J,4,FALSE),""),IF(ISBLANK(B21)=FALSE,VLOOKUP(B21,Data_source!A:J,5,FALSE),"")) -> 3-phase power measurement terminal, max. 500 V AC 3~, max. 1 A, via measuring transformers x A/1A | D21: =IF(ISBLANK(B21)=FALSE,IF(VLOOKUP(B21,Data_source!A:J,2,FALSE)="---","",VLOOKUP(B21,Data_source!A:J,2,FALSE)),"") -> -120 | E21: =IF(F21<>"",D21,IF(D21>0,D21,IF(E20="",D21,E20+D21))) -> 850 | F21: =IF(ISBLANK(B21)=FALSE,IF(VLOOKUP(B21,Data_source!A:J,3,FALSE)="---","",VLOOKUP(B21,Data_source!A:J,3,FALSE)),"") | G21: =IF(F21>0, F21, IF(F21="", "", IF(G20="", F21, G20+F21))) | H21: =IF(ISBLANK(B21)=FALSE,IF(VLOOKUP(B21,Data_source!A:J,6,FALSE)="---","",VLOOKUP(B21,Data_source!A:J,6,FALSE)),"") -> 12 | I21: =IF(H21="","",IF(H20="",H21,H21+I20)) -> 152 | J21: =IF(ISBLANK(B21)=FALSE,IF(VLOOKUP(B21,Data_source!A:J,7,FALSE)=0,"",VLOOKUP(B21,Data_source!A:J,7,FALSE)),"") | K21: =IF(ISBLANK(B21)=FALSE,IF(VLOOKUP(B21,Data_source!A:J,8,FALSE)=0,"",VLOOKUP(B21,Data_source!A:J,8,FALSE)),"") | L21: =IF(ISBLANK(B21)=FALSE,IF(VLOOKUP(B21,Data_source!A:J,9,FALSE)=0,"",VLOOKUP(B21,Data_source!A:J,9,FALSE)),"")
A22: 11 | B22: EL9011 | C22: =IF($E$5=1,IF(ISBLANK(B22)=FALSE,VLOOKUP(B22,Data_source!A:J,4,FALSE),""),IF(ISBLANK(B22)=FALSE,VLOOKUP(B22,Data_source!A:J,5,FALSE),"")) -> Bus end cap | D22: =IF(ISBLANK(B22)=FALSE,IF(VLOOKUP(B22,Data_source!A:J,2,FALSE)="---","",VLOOKUP(B22,Data_source!A:J,2,FALSE)),"") | E22: =IF(F22<>"",D22,IF(D22>0,D22,IF(E21="",D22,E21+D22))) | F22: =IF(ISBLANK(B22)=FALSE,IF(VLOOKUP(B22,Data_source!A:J,3,FALSE)="---","",VLOOKUP(B22,Data_source!A:J,3,FALSE)),"") | G22: =IF(F22>0, F22, IF(F22="", "", IF(G21="", F22, G21+F22))) | H22: =IF(ISBLANK(B22)=FALSE,IF(VLOOKUP(B22,Data_source!A:J,6,FALSE)="---","",VLOOKUP(B22,Data_source!A:J,6,FALSE)),"") -> 5 | I22: =IF(H22="","",IF(H21="",H22,H22+I21)) -> 157 | J22: =IF(ISBLANK(B22)=FALSE,IF(VLOOKUP(B22,Data_source!A:J,7,FALSE)=0,"",VLOOKUP(B22,Data_source!A:J,7,FALSE)),"") -> --- | K22: =IF(ISBLANK(B22)=FALSE,IF(VLOOKUP(B22,Data_source!A:J,8,FALSE)=0,"",VLOOKUP(B22,Data_source!A:J,8,FALSE)),"") -> --- | L22: =IF(ISBLANK(B22)=FALSE,IF(VLOOKUP(B22,Data_source!A:J,9,FALSE)=0,"",VLOOKUP(B22,Data_source!A:J,9,FALSE)),"") -> ---
A23: 12 | C23: =IF($E$5=1,IF(ISBLANK(B23)=FALSE,VLOOKUP(B23,Data_source!A:J,4,FALSE),""),IF(ISBLANK(B23)=FALSE,VLOOKUP(B23,Data_source!A:J,5,FALSE),"")) | D23: =IF(ISBLANK(B23)=FALSE,IF(VLOOKUP(B23,Data_source!A:J,2,FALSE)="---","",VLOOKUP(B23,Data_source!A:J,2,FALSE)),"") | E23: =IF(F23<>"",D23,IF(D23>0,D23,IF(E22="",D23,E22+D23))) | F23: =IF(ISBLANK(B23)=FALSE,IF(VLOOKUP(B23,Data_source!A:J,3,FALSE)="---","",VLOOKUP(B23,Data_source!A:J,3,FALSE)),"") | G23: =IF(F23>0, F23, IF(F23="", "", IF(G22="", F23, G22+F23))) | H23: =IF(ISBLANK(B23)=FALSE,IF(VLOOKUP(B23,Data_source!A:J,6,FALSE)="---","",VLOOKUP(B23,Data_source!A:J,6,FALSE)),"") | I23: =IF(H23="","",IF(H22="",H23,H23+I22)) | J23: =IF(ISBLANK(B23)=FALSE,IF(VLOOKUP(B23,Data_source!A:J,7,FALSE)=0,"",VLOOKUP(B23,Data_source!A:J,7,FALSE)),"") | K23: =IF(ISBLANK(B23)=FALSE,IF(VLOOKUP(B23,Data_source!A:J,8,FALSE)=0,"",VLOOKUP(B23,Data_source!A:J,8,FALSE)),"") | L23: =IF(ISBLANK(B23)=FALSE,IF(VLOOKUP(B23,Data_source!A:J,9,FALSE)=0,"",VLOOKUP(B23,Data_source!A:J,9,FALSE)),"")
A24: 13 | C24: =IF($E$5=1,IF(ISBLANK(B24)=FALSE,VLOOKUP(B24,Data_source!A:J,4,FALSE),""),IF(ISBLANK(B24)=FALSE,VLOOKUP(B24,Data_source!A:J,5,FALSE),"")) | D24: =IF(ISBLANK(B24)=FALSE,IF(VLOOKUP(B24,Data_source!A:J,2,FALSE)="---","",VLOOKUP(B24,Data_source!A:J,2,FALSE)),"") | E24: =IF(F24<>"",D24,IF(D24>0,D24,IF(E23="",D24,E23+D24))) | F24: =IF(ISBLANK(B24)=FALSE,IF(VLOOKUP(B24,Data_source!A:J,3,FALSE)="---","",VLOOKUP(B24,Data_source!A:J,3,FALSE)),"") | G24: =IF(F24>0, F24, IF(F24="", "", IF(G23="", F24, G23+F24))) | H24: =IF(ISBLANK(B24)=FALSE,IF(VLOOKUP(B24,Data_source!A:J,6,FALSE)="---","",VLOOKUP(B24,Data_source!A:J,6,FALSE)),"") | I24: =IF(H24="","",IF(H23="",H24,H24+I23)) | J24: =IF(ISBLANK(B24)=FALSE,IF(VLOOKUP(B24,Data_source!A:J,7,FALSE)=0,"",VLOOKUP(B24,Data_source!A:J,7,FALSE)),"") | K24: =IF(ISBLANK(B24)=FALSE,IF(VLOOKUP(B24,Data_source!A:J,8,FALSE)=0,"",VLOOKUP(B24,Data_source!A:J,8,FALSE)),"") | L24: =IF(ISBLANK(B24)=FALSE,IF(VLOOKUP(B24,Data_source!A:J,9,FALSE)=0,"",VLOOKUP(B24,Data_source!A:J,9,FALSE)),"")
A25: 14 | C25: =IF($E$5=1,IF(ISBLANK(B25)=FALSE,VLOOKUP(B25,Data_source!A:J,4,FALSE),""),IF(ISBLANK(B25)=FALSE,VLOOKUP(B25,Data_source!A:J,5,FALSE),"")) | D25: =IF(ISBLANK(B25)=FALSE,IF(VLOOKUP(B25,Data_source!A:J,2,FALSE)="---","",VLOOKUP(B25,Data_source!A:J,2,FALSE)),"") | E25: =IF(F25<>"",D25,IF(D25>0,D25,IF(E24="",D25,E24+D25))) | F25: =IF(ISBLANK(B25)=FALSE,IF(VLOOKUP(B25,Data_source!A:J,3,FALSE)="---","",VLOOKUP(B25,Data_source!A:J,3,FALSE)),"") | G25: =IF(F25>0, F25, IF(F25="", "", IF(G24="", F25, G24+F25))) | H25: =IF(ISBLANK(B25)=FALSE,IF(VLOOKUP(B25,Data_source!A:J,6,FALSE)="---","",VLOOKUP(B25,Data_source!A:J,6,FALSE)),"") | I25: =IF(H25="","",IF(H24="",H25,H25+I24)) | J25: =IF(ISBLANK(B25)=FALSE,IF(VLOOKUP(B25,Data_source!A:J,7,FALSE)=0,"",VLOOKUP(B25,Data_source!A:J,7,FALSE)),"") | K25: =IF(ISBLANK(B25)=FALSE,IF(VLOOKUP(B25,Data_source!A:J,8,FALSE)=0,"",VLOOKUP(B25,Data_source!A:J,8,FALSE)),"") | L25: =IF(ISBLANK(B25)=FALSE,IF(VLOOKUP(B25,Data_source!A:J,9,FALSE)=0,"",VLOOKUP(B25,Data_source!A:J,9,FALSE)),"")
A26: 15 | C26: =IF($E$5=1,IF(ISBLANK(B26)=FALSE,VLOOKUP(B26,Data_source!A:J,4,FALSE),""),IF(ISBLANK(B26)=FALSE,VLOOKUP(B26,Data_source!A:J,5,FALSE),"")) | D26: =IF(ISBLANK(B26)=FALSE,IF(VLOOKUP(B26,Data_source!A:J,2,FALSE)="---","",VLOOKUP(B26,Data_source!A:J,2,FALSE)),"") | E26: =IF(F26<>"",D26,IF(D26>0,D26,IF(E25="",D26,E25+D26))) | F26: =IF(ISBLANK(B26)=FALSE,IF(VLOOKUP(B26,Data_source!A:J,3,FALSE)="---","",VLOOKUP(B26,Data_source!A:J,3,FALSE)),"") | G26: =IF(F26>0, F26, IF(F26="", "", IF(G25="", F26, G25+F26))) | H26: =IF(ISBLANK(B26)=FALSE,IF(VLOOKUP(B26,Data_source!A:J,6,FALSE)="---","",VLOOKUP(B26,Data_source!A:J,6,FALSE)),"") | I26: =IF(H26="","",IF(H25="",H26,H26+I25)) | J26: =IF(ISBLANK(B26)=FALSE,IF(VLOOKUP(B26,Data_source!A:J,7,FALSE)=0,"",VLOOKUP(B26,Data_source!A:J,7,FALSE)),"") | K26: =IF(ISBLANK(B26)=FALSE,IF(VLOOKUP(B26,Data_source!A:J,8,FALSE)=0,"",VLOOKUP(B26,Data_source!A:J,8,FALSE)),"") | L26: =IF(ISBLANK(B26)=FALSE,IF(VLOOKUP(B26,Data_source!A:J,9,FALSE)=0,"",VLOOKUP(B26,Data_source!A:J,9,FALSE)),"")
A27: 16 | C27: =IF($E$5=1,IF(ISBLANK(B27)=FALSE,VLOOKUP(B27,Data_source!A:J,4,FALSE),""),IF(ISBLANK(B27)=FALSE,VLOOKUP(B27,Data_source!A:J,5,FALSE),"")) | D27: =IF(ISBLANK(B27)=FALSE,IF(VLOOKUP(B27,Data_source!A:J,2,FALSE)="---","",VLOOKUP(B27,Data_source!A:J,2,FALSE)),"") | E27: =IF(F27<>"",D27,IF(D27>0,D27,IF(E26="",D27,E26+D27))) | F27: =IF(ISBLANK(B27)=FALSE,IF(VLOOKUP(B27,Data_source!A:J,3,FALSE)="---","",VLOOKUP(B27,Data_source!A:J,3,FALSE)),"") | G27: =IF(F27>0, F27, IF(F27="", "", IF(G26="", F27, G26+F27))) | H27: =IF(ISBLANK(B27)=FALSE,IF(VLOOKUP(B27,Data_source!A:J,6,FALSE)="---","",VLOOKUP(B27,Data_source!A:J,6,FALSE)),"") | I27: =IF(H27="","",IF(H26="",H27,H27+I26)) | J27: =IF(ISBLANK(B27)=FALSE,IF(VLOOKUP(B27,Data_source!A:J,7,FALSE)=0,"",VLOOKUP(B27,Data_source!A:J,7,FALSE)),"") | K27: =IF(ISBLANK(B27)=FALSE,IF(VLOOKUP(B27,Data_source!A:J,8,FALSE)=0,"",VLOOKUP(B27,Data_source!A:J,8,FALSE)),"") | L27: =IF(ISBLANK(B27)=FALSE,IF(VLOOKUP(B27,Data_source!A:J,9,FALSE)=0,"",VLOOKUP(B27,Data_source!A:J,9,FALSE)),"")
A28: 17 | C28: =IF($E$5=1,IF(ISBLANK(B28)=FALSE,VLOOKUP(B28,Data_source!A:J,4,FALSE),""),IF(ISBLANK(B28)=FALSE,VLOOKUP(B28,Data_source!A:J,5,FALSE),"")) | D28: =IF(ISBLANK(B28)=FALSE,IF(VLOOKUP(B28,Data_source!A:J,2,FALSE)="---","",VLOOKUP(B28,Data_source!A:J,2,FALSE)),"") | E28: =IF(F28<>"",D28,IF(D28>0,D28,IF(E27="",D28,E27+D28))) | F28: =IF(ISBLANK(B28)=FALSE,IF(VLOOKUP(B28,Data_source!A:J,3,FALSE)="---","",VLOOKUP(B28,Data_source!A:J,3,FALSE)),"") | G28: =IF(F28>0, F28, IF(F28="", "", IF(G27="", F28, G27+F28))) | H28: =IF(ISBLANK(B28)=FALSE,IF(VLOOKUP(B28,Data_source!A:J,6,FALSE)="---","",VLOOKUP(B28,Data_source!A:J,6,FALSE)),"") | I28: =IF(H28="","",IF(H27="",H28,H28+I27)) | J28: =IF(ISBLANK(B28)=FALSE,IF(VLOOKUP(B28,Data_source!A:J,7,FALSE)=0,"",VLOOKUP(B28,Data_source!A:J,7,FALSE)),"") | K28: =IF(ISBLANK(B28)=FALSE,IF(VLOOKUP(B28,Data_source!A:J,8,FALSE)=0,"",VLOOKUP(B28,Data_source!A:J,8,FALSE)),"") | L28: =IF(ISBLANK(B28)=FALSE,IF(VLOOKUP(B28,Data_source!A:J,9,FALSE)=0,"",VLOOKUP(B28,Data_source!A:J,9,FALSE)),"")
A29: 18 | C29: =IF($E$5=1,IF(ISBLANK(B29)=FALSE,VLOOKUP(B29,Data_source!A:J,4,FALSE),""),IF(ISBLANK(B29)=FALSE,VLOOKUP(B29,Data_source!A:J,5,FALSE),"")) | D29: =IF(ISBLANK(B29)=FALSE,IF(VLOOKUP(B29,Data_source!A:J,2,FALSE)="---","",VLOOKUP(B29,Data_source!A:J,2,FALSE)),"") | E29: =IF(F29<>"",D29,IF(D29>0,D29,IF(E28="",D29,E28+D29))) | F29: =IF(ISBLANK(B29)=FALSE,IF(VLOOKUP(B29,Data_source!A:J,3,FALSE)="---","",VLOOKUP(B29,Data_source!A:J,3,FALSE)),"") | G29: =IF(F29>0, F29, IF(F29="", "", IF(G28="", F29, G28+F29))) | H29: =IF(ISBLANK(B29)=FALSE,IF(VLOOKUP(B29,Data_source!A:J,6,FALSE)="---","",VLOOKUP(B29,Data_source!A:J,6,FALSE)),"") | I29: =IF(H29="","",IF(H28="",H29,H29+I28)) | J29: =IF(ISBLANK(B29)=FALSE,IF(VLOOKUP(B29,Data_source!A:J,7,FALSE)=0,"",VLOOKUP(B29,Data_source!A:J,7,FALSE)),"") | K29: =IF(ISBLANK(B29)=FALSE,IF(VLOOKUP(B29,Data_source!A:J,8,FALSE)=0,"",VLOOKUP(B29,Data_source!A:J,8,FALSE)),"") | L29: =IF(ISBLANK(B29)=FALSE,IF(VLOOKUP(B29,Data_source!A:J,9,FALSE)=0,"",VLOOKUP(B29,Data_source!A:J,9,FALSE)),"")
A30: 19 | C30: =IF($E$5=1,IF(ISBLANK(B30)=FALSE,VLOOKUP(B30,Data_source!A:J,4,FALSE),""),IF(ISBLANK(B30)=FALSE,VLOOKUP(B30,Data_source!A:J,5,FALSE),"")) | D30: =IF(ISBLANK(B30)=FALSE,IF(VLOOKUP(B30,Data_source!A:J,2,FALSE)="---","",VLOOKUP(B30,Data_source!A:J,2,FALSE)),"") | E30: =IF(F30<>"",D30,IF(D30>0,D30,IF(E29="",D30,E29+D30))) | F30: =IF(ISBLANK(B30)=FALSE,IF(VLOOKUP(B30,Data_source!A:J,3,FALSE)="---","",VLOOKUP(B30,Data_source!A:J,3,FALSE)),"") | G30: =IF(F30>0, F30, IF(F30="", "", IF(G29="", F30, G29+F30))) | H30: =IF(ISBLANK(B30)=FALSE,IF(VLOOKUP(B30,Data_source!A:J,6,FALSE)="---","",VLOOKUP(B30,Data_source!A:J,6,FALSE)),"") | I30: =IF(H30="","",IF(H29="",H30,H30+I29)) | J30: =IF(ISBLANK(B30)=FALSE,IF(VLOOKUP(B30,Data_source!A:J,7,FALSE)=0,"",VLOOKUP(B30,Data_source!A:J,7,FALSE)),"") | K30: =IF(ISBLANK(B30)=FALSE,IF(VLOOKUP(B30,Data_source!A:J,8,FALSE)=0,"",VLOOKUP(B30,Data_source!A:J,8,FALSE)),"") | L30: =IF(ISBLANK(B30)=FALSE,IF(VLOOKUP(B30,Data_source!A:J,9,FALSE)=0,"",VLOOKUP(B30,Data_source!A:J,9,FALSE)),"")
A31: 20 | C31: =IF($E$5=1,IF(ISBLANK(B31)=FALSE,VLOOKUP(B31,Data_source!A:J,4,FALSE),""),IF(ISBLANK(B31)=FALSE,VLOOKUP(B31,Data_source!A:J,5,FALSE),"")) | D31: =IF(ISBLANK(B31)=FALSE,IF(VLOOKUP(B31,Data_source!A:J,2,FALSE)="---","",VLOOKUP(B31,Data_source!A:J,2,FALSE)),"") | E31: =IF(F31<>"",D31,IF(D31>0,D31,IF(E30="",D31,E30+D31))) | F31: =IF(ISBLANK(B31)=FALSE,IF(VLOOKUP(B31,Data_source!A:J,3,FALSE)="---","",VLOOKUP(B31,Data_source!A:J,3,FALSE)),"") | G31: =IF(F31>0, F31, IF(F31="", "", IF(G30="", F31, G30+F31))) | H31: =IF(ISBLANK(B31)=FALSE,IF(VLOOKUP(B31,Data_source!A:J,6,FALSE)="---","",VLOOKUP(B31,Data_source!A:J,6,FALSE)),"") | I31: =IF(H31="","",IF(H30="",H31,H31+I30)) | J31: =IF(ISBLANK(B31)=FALSE,IF(VLOOKUP(B31,Data_source!A:J,7,FALSE)=0,"",VLOOKUP(B31,Data_source!A:J,7,FALSE)),"") | K31: =IF(ISBLANK(B31)=FALSE,IF(VLOOKUP(B31,Data_source!A:J,8,FALSE)=0,"",VLOOKUP(B31,Data_source!A:J,8,FALSE)),"") | L31: =IF(ISBLANK(B31)=FALSE,IF(VLOOKUP(B31,Data_source!A:J,9,FALSE)=0,"",VLOOKUP(B31,Data_source!A:J,9,FALSE)),"")
A32: 21 | C32: =IF($E$5=1,IF(ISBLANK(B32)=FALSE,VLOOKUP(B32,Data_source!A:J,4,FALSE),""),IF(ISBLANK(B32)=FALSE,VLOOKUP(B32,Data_source!A:J,5,FALSE),"")) | D32: =IF(ISBLANK(B32)=FALSE,IF(VLOOKUP(B32,Data_source!A:J,2,FALSE)="---","",VLOOKUP(B32,Data_source!A:J,2,FALSE)),"") | E32: =IF(F32<>"",D32,IF(D32>0,D32,IF(E31="",D32,E31+D32))) | F32: =IF(ISBLANK(B32)=FALSE,IF(VLOOKUP(B32,Data_source!A:J,3,FALSE)="---","",VLOOKUP(B32,Data_source!A:J,3,FALSE)),"") | G32: =IF(F32>0, F32, IF(F32="", "", IF(G31="", F32, G31+F32))) | H32: =IF(ISBLANK(B32)=FALSE,IF(VLOOKUP(B32,Data_source!A:J,6,FALSE)="---","",VLOOKUP(B32,Data_source!A:J,6,FALSE)),"") | I32: =IF(H32="","",IF(H31="",H32,H32+I31)) | J32: =IF(ISBLANK(B32)=FALSE,IF(VLOOKUP(B32,Data_source!A:J,7,FALSE)=0,"",VLOOKUP(B32,Data_source!A:J,7,FALSE)),"") | K32: =IF(ISBLANK(B32)=FALSE,IF(VLOOKUP(B32,Data_source!A:J,8,FALSE)=0,"",VLOOKUP(B32,Data_source!A:J,8,FALSE)),"") | L32: =IF(ISBLANK(B32)=FALSE,IF(VLOOKUP(B32,Data_source!A:J,9,FALSE)=0,"",VLOOKUP(B32,Data_source!A:J,9,FALSE)),"")
A33: 22 | C33: =IF($E$5=1,IF(ISBLANK(B33)=FALSE,VLOOKUP(B33,Data_source!A:J,4,FALSE),""),IF(ISBLANK(B33)=FALSE,VLOOKUP(B33,Data_source!A:J,5,FALSE),"")) | D33: =IF(ISBLANK(B33)=FALSE,IF(VLOOKUP(B33,Data_source!A:J,2,FALSE)="---","",VLOOKUP(B33,Data_source!A:J,2,FALSE)),"") | E33: =IF(F33<>"",D33,IF(D33>0,D33,IF(E32="",D33,E32+D33))) | F33: =IF(ISBLANK(B33)=FALSE,IF(VLOOKUP(B33,Data_source!A:J,3,FALSE)="---","",VLOOKUP(B33,Data_source!A:J,3,FALSE)),"") | G33: =IF(F33>0, F33, IF(F33="", "", IF(G32="", F33, G32+F33))) | H33: =IF(ISBLANK(B33)=FALSE,IF(VLOOKUP(B33,Data_source!A:J,6,FALSE)="---","",VLOOKUP(B33,Data_source!A:J,6,FALSE)),"") | I33: =IF(H33="","",IF(H32="",H33,H33+I32)) | J33: =IF(ISBLANK(B33)=FALSE,IF(VLOOKUP(B33,Data_source!A:J,7,FALSE)=0,"",VLOOKUP(B33,Data_source!A:J,7,FALSE)),"") | K33: =IF(ISBLANK(B33)=FALSE,IF(VLOOKUP(B33,Data_source!A:J,8,FALSE)=0,"",VLOOKUP(B33,Data_source!A:J,8,FALSE)),"") | L33: =IF(ISBLANK(B33)=FALSE,IF(VLOOKUP(B33,Data_source!A:J,9,FALSE)=0,"",VLOOKUP(B33,Data_source!A:J,9,FALSE)),"")
A34: 23 | C34: =IF($E$5=1,IF(ISBLANK(B34)=FALSE,VLOOKUP(B34,Data_source!A:J,4,FALSE),""),IF(ISBLANK(B34)=FALSE,VLOOKUP(B34,Data_source!A:J,5,FALSE),"")) | D34: =IF(ISBLANK(B34)=FALSE,IF(VLOOKUP(B34,Data_source!A:J,2,FALSE)="---","",VLOOKUP(B34,Data_source!A:J,2,FALSE)),"") | E34: =IF(F34<>"",D34,IF(D34>0,D34,IF(E33="",D34,E33+D34))) | F34: =IF(ISBLANK(B34)=FALSE,IF(VLOOKUP(B34,Data_source!A:J,3,FALSE)="---","",VLOOKUP(B34,Data_source!A:J,3,FALSE)),"") | G34: =IF(F34>0, F34, IF(F34="", "", IF(G33="", F34, G33+F34))) | H34: =IF(ISBLANK(B34)=FALSE,IF(VLOOKUP(B34,Data_source!A:J,6,FALSE)="---","",VLOOKUP(B34,Data_source!A:J,6,FALSE)),"") | I34: =IF(H34="","",IF(H33="",H34,H34+I33)) | J34: =IF(ISBLANK(B34)=FALSE,IF(VLOOKUP(B34,Data_source!A:J,7,FALSE)=0,"",VLOOKUP(B34,Data_source!A:J,7,FALSE)),"") | K34: =IF(ISBLANK(B34)=FALSE,IF(VLOOKUP(B34,Data_source!A:J,8,FALSE)=0,"",VLOOKUP(B34,Data_source!A:J,8,FALSE)),"") | L34: =IF(ISBLANK(B34)=FALSE,IF(VLOOKUP(B34,Data_source!A:J,9,FALSE)=0,"",VLOOKUP(B34,Data_source!A:J,9,FALSE)),"")
... A311: 300 | C311: =IF($E$5=1,IF(ISBLANK(B311)=FALSE,VLOOKUP(B311,Data_source!A:J,4,FALSE),""),IF(ISBLANK(B311)=FALSE,VLOOKUP(B311,Data_source!A:J,5,FALSE),"")) | D311: =IF(ISBLANK(B311)=FALSE,IF(VLOOKUP(B311,Data_source!A:J,2,FALSE)="---","",VLOOKUP(B311,Data_source!A:J,2,FALSE)),"") | E311: =IF(F311<>"",D311,IF(D311>0,D311,IF(E310="",D311,E310+D311))) | F311: =IF(ISBLANK(B311)=FALSE,IF(VLOOKUP(B311,Data_source!A:J,3,FALSE)="---","",VLOOKUP(B311,Data_source!A:J,3,FALSE)),"") | G311: =IF(F311>0, F311, IF(F311="", "", IF(G310="", F311, G310+F311))) | H311: =IF(ISBLANK(B311)=FALSE,IF(VLOOKUP(B311,Data_source!A:J,6,FALSE)="---","",VLOOKUP(B311,Data_source!A:J,6,FALSE)),"") | I311: =IF(H311="","",IF(H310="",H311,H311+I310)) | J311: =IF(ISBLANK(B311)=FALSE,IF(VLOOKUP(B311,Data_source!A:J,7,FALSE)=0,"",VLOOKUP(B311,Data_source!A:J,7,FALSE)),"") | K311: =IF(ISBLANK(B311)=FALSE,IF(VLOOKUP(B311,Data_source!A:J,8,FALSE)=0,"",VLOOKUP(B311,Data_source!A:J,8,FALSE)),"") | L311: =IF(ISBLANK(B311)=FALSE,IF(VLOOKUP(B311,Data_source!A:J,9,FALSE)=0,"",VLOOKUP(B311,Data_source!A:J,9,FALSE)),"")

Sheet Data_source
A1: =IF(System_configuration!E5=1, "Produkt", "Product") -> Product | B1: =IF(System_configuration!E5=1, "E-Bus Strom (mA)", "E-Bus current (mA)") -> E-Bus current (mA) | C1: =IF(System_configuration!E5=1, "K-Bus Strom (mA)", "K-Bus current (mA)") -> K-Bus current (mA) | D1: =IF(System_configuration!E5=1, "Produkt Beschreibung (German)", "Product Description (German)") -> Product Description (German) | E1: =IF(System_configuration!E5=1, "Produkt Beschreibung (English)", "Product Description (English)") -> Product Description (English) | F1: =IF(System_configuration!E5=1, "Produkt Breite (mm)", "Product width (mm)") -> Product width (mm) | G1: =IF(System_configuration!E5=1, "Power Kontakt +", "Power contact +") -> Power contact + | H1: =IF(System_configuration!E5=1, "Power Kontakt -", "Power contact -") -> Power contact - | I1: =IF(System_configuration!E5=1, "Power Kontakt PE", "Power contact PE") -> Power contact PE | J1: =IF(System_configuration!E5=1, "Anzahl der Produkte (Stück)", "Number of Products (piece)") -> Number of Products (piece)
A2: BC3100 | B2: --- | C2: 1750 | D2: Busklemmen Controller mit integrierter IEC 61131-3-SPS, 32 kByte Programmspeicher, PROFIBUS-Schnittstelle, 12 MBaud | E2: Bus Terminal Controller with integrated IEC 61131-3 PLC, 32 kbytes program memory, PROFIBUS interface, 12 Mbaud | F2: 49 | G2: -T- | H2: -T- | I2: -T- | J2: =COUNTIF(System_configuration!B:B,A2) -> 0
A3: BC3150 | B3: --- | C3: 1000 | D3: "Compact"-Busklemmen Controller mit integrierter IEC 61131-3-SPS, 48 kByte Programmspeicher, PROFIBUS-Schnittstelle, 12 MBaud | E3: “Compact“ Bus Terminal Controller with integrated IEC 61131-3 PLC, 48 kbytes program memory, PROFIBUS interface, 12 Mbaud | F3: 44 | G3: -T- | H3: -T- | J3: =COUNTIF(System_configuration!B:B,A3) -> 0
A4: BC5150 | B4: --- | C4: 1000 | D4: „Compact“-Busklemmen Controller mit integrierter IEC 61131-3-SPS, 48 kByte Programmspeicher, CANopen-Schnittstelle, 1 MBaud | E4: “Compact“ Bus Terminal Controller with integrated IEC 61131-3 PLC, 48 kbytes program memory, CANopen interface, 1 Mbaud | F4: 44 | G4: -T- | H4: -T- | J4: =COUNTIF(System_configuration!B:B,A4) -> 0
A5: BC5250 | B5: --- | C5: 1000 | D5: „Compact“-Busklemmen Controller mit integrierter IEC 61131-3-SPS, 48 kByte Programmspeicher, DeviceNet-Schnittstelle, 500 kBaud | E5: “Compact“ Bus Terminal Controller with integrated IEC 61131-3 PLC, 48 kbytes program memory, DeviceNet interface, 500 kbaud | F5: 49 | G5: -T- | H5: -T- | J5: =COUNTIF(System_configuration!B:B,A5) -> 0
A6: BC7300 | B6: --- | C6: 1750 | D6: Busklemmen Controller mit integrierter IEC 61131-3-SPS, 32 kByte Programmspeicher, Modbus-Schnittstelle | E6: Bus Terminal Controller with integrated IEC 61131-3 PLC, 32 kbytes program memory, Modbus interface | F6: 49 | G6: -T- | H6: -T- | I6: -T- | J6: =COUNTIF(System_configuration!B:B,A6) -> 0
A7: BC8050 | B7: --- | C7: 1000 | D7: "Compact"-Busklemmen Controller mit integrierter IEC 61131-3-SPS, 48 kByte Programmspeicher, RS485-Schnittstelle | E7: “Compact“ Bus Terminal Controller with integrated IEC 61131-3 PLC, 48 kbytes program memory, RS2485 interface | F7: 44 | G7: -T- | H7: -T- | J7: =COUNTIF(System_configuration!B:B,A7) -> 0
A8: BC8150 | B8: --- | C8: 1000 | D8: "Compact"-Busklemmen Controller mit integrierter IEC 61131-3-SPS, 48 kByte Programmspeicher, RS232-Schnittstelle | E8: “Compact“ Bus Terminal Controller with integrated IEC 61131-3 PLC, 48 kbytes program memory, RS232 interface | F8: 44 | G8: -T- | H8: -T- | J8: =COUNTIF(System_configuration!B:B,A8) -> 0
A9: BC9000 | B9: --- | C9: 1750 | D9: Busklemmen Controller mit integrierter IEC 61131-3-SPS, 64 kByte Programmspeicher, Ethernet TCP/IP-Schnittstelle; Ethernet-Protokolle TwinCAT ADS, Modbus TCP | E9: Bus Terminal Controller with integrated IEC 61131-3 PLC, 64 kbytes program memory, Ethernet TCP/IP interface; Ethernet protocols TwinCAT ADS, Modbus TCP | F9: 49 | G9: -T- | H9: -T- | I9: -T- | J9: =COUNTIF(System_configuration!B:B,A9) -> 0
A10: BC9020 | B10: --- | C10: 1750 | D10: „Economy plus“-Busklemmen-Controller mit integrierter IEC 61131-3-SPS, 128 kByte Programmspeicher, Ethernet-TCP/IP-Schnittstelle; Ethernet-Protokolle TwinCAT ADS, Modbus TCP | E10: “Economy plus” Bus Terminal Controller with integrated IEC 61131-3 PLC, 128 kbytes program memory, Ethernet TCP/IP interface; Ethernet protocols TwinCAT ADS, Modbus TCP | F10: 49 | G10: -T- | H10: -T- | I10: -T- | J10: =COUNTIF(System_configuration!B:B,A10) -> 0
A11: BC9050 | B11: --- | C11: 1000 | D11: „Compact“-Busklemmen-Controller mit integrierter IEC 61131-3-SPS, 48 kByte Programmspeicher, Ethernet TCP/IP-Schnittstelle; Ethernet-Protokolle TwinCAT ADS, Modbus TCP | E11: “Compact“ Bus Terminal Controller with integrated IEC 61131-3 PLC, 48 kbytes program memory, Ethernet TCP/IP interface; Ethernet protocols TwinCAT ADS, Modbus TCP | F11: 44 | G11: -T- | H11: -T- | J11: =COUNTIF(System_configuration!B:B,A11) -> 0
A12: BC9100 | B12: --- | C12: 1750 | D12: Busklemmen Controller mit integrierter IEC 61131-3-SPS, 64 kByte Programmspeicher, Ethernet TCP/IP-Schnittstelle und integriertem 2-Kanal-Switch; Ethernet-Protokolle TwinCAT ADS, Modbus TCP | E12: Bus Terminal Controller with integrated IEC 61131-3 PLC, 64 kbytes program memory, Ethernet TCP/IP interface and integrated 2-channel switch; Ethernet protocols TwinCAT ADS, Modbus TCP | F12: 49 | G12: -T- | H12: -T- | I12: -T- | J12: =COUNTIF(System_configuration!B:B,A12) -> 0
A13: BC9120 | B13: --- | C13: 1750 | D13: „Economy plus“-Busklemmen-Controller mit integrierter IEC 61131-3-SPS, 128 kByte Programmspeicher, Ethernet-TCP/IP-Schnittstelle und integriertem 2-Kanal-Switch; Ethernet-Protokolle TwinCAT ADS, Modbus TCP | E13: “Economy plus” Bus Terminal Controller with integrated IEC 61131-3 PLC, 128 kbytes program memory, Ethernet TCP/IP interface and integrated 2-channel switch; Ethernet protocols TwinCAT ADS, Modbus TCP | F13: 49 | G13: -T- | H13: -T- | I13: -T- | J13: =COUNTIF(System_configuration!B:B,A13) -> 0
A14: BC9191 | B14: --- | C14: 200 | D14: Building-Automation-Raum-Controller mit integrierter IEC 61131-3-SPS, Ethernet-TCP/IP-Schnittstelle und integriertem 2-Kanal-Switch – Programmspeicher: 48 kByte – Spannungsversorgung: 230 V AC – Ethernet-Protokolle: TwinCAT ADS, Modbus TCP – Sub-Bussystem: 1 x Anbindung an EnOcean KL6583 – K-Bus-Interface – on-board I/Os: – 3 digitale Eingänge – 1 analoger Eingang PT/NI1000 – 1 analoger Eingang, Widerstandsmessung zur Sollwertvorgabe (0…10 kΩ) – 3 analoge Eingänge 0...10 V – 1 digitaler Ausgang für LED, 10 mA – 1 digitaler Relais-Ausgang 230 V AC, 10 A – 3 digitale Relais-Ausgänge 230 V AC, 1 A – 2 digitale Triac-Ausgänge 230 V AC, 1 A – 2 analoge Ausgänge 0…10 V | E14: Bus Terminal Controller with integrated IEC 61131-3 PLC, Ethernet TCP/IP interface and integrated 2-channel switch – Program memory: 48 kbytes – Supply voltage: 230 V AC – Ethernet protocols: TwinCAT ADS, Modbus TCP – Sub bus system: 1 connection to EnOcean KL6583 – K-bus interface – on board I/Os: – 3 digital inputs – 1 analog input PT/NI1000 – 1 analog input, resistance measurement for set value specification (0…10 kΩ) – 3 analog inputs 0...10 V – 1 digital output for LED, 10 mA – 1 digital relay output 230 V AC, 10 A – 3 digital relay outputs 230 V AC, 1 A – 2 digital triac outputs 230 V AC, 1 A – 2 analog outputs 0…10 V | F14: 122 | J14: =COUNTIF(System_configuration!B:B,A14) -> 0
A15: BC9191-0100 | B15: --- | C15: 200 | D15: Building-Automation-Raum-Controller mit integrierter IEC 61131-3-SPS, Ethernet-TCP/IP-Schnittstelle und integriertem 2-Kanal-Switch – Programmspeicher: 128 kByte – Spannungsversorgung: 230 V AC – Ethernet-Protokolle: TwinCAT ADS, Modbus TCP – Sub-Bussystem: 1 x RS485 – K-Bus-Interface – on-board I/Os: – 3 digitale Eingänge – 1 analoger Eingang PT/NI1000 – 1 analoger Eingang, Widerstandsmessung zur Sollwertvorgabe (0…10 kΩ) – 3 analoge Eingänge 0...10 V – 1 digitaler Ausgang für LED, 10 mA – 1 digitaler Relais-Ausgang 230 V AC, 10 A – 3 digitale Relais-Ausgänge 230 V AC, 1 A – 2 digitale Triac-Ausgänge 230 V AC, 1 A – 2 analoge Ausgänge 0…10 V | E15: Bus Terminal Controller with integrated IEC 61131-3 PLC, Ethernet TCP/IP interface and integrated 2-channel switch – Program memory: 128 kbytes – Supply voltage: 230 V AC – Ethernet protocols: TwinCAT ADS, Modbus TCP – Sub bus system: 1 x RS485 – K-bus interface – on board I/Os: – 3 digital inputs – 1 analog input 1 x Pt/NI1000 – 1 analog input, resistance measurement for set value specification (0…10 kΩ) – 3 analog inputs 0...10 V – 1 digital output for LED, 10 mA – 1 digital relay output 230 V AC, 10 A – 3 digital relay outputs 230 V AC, 1 A – 2 digital triac outputs 230 V AC, 1 A – 2 analog outputs 0…10 V | F15: 122 | J15: =COUNTIF(System_configuration!B:B,A15) -> 0
A16: BK1120 | B16: --- | C16: 1750 | D16: EtherCAT-„Economy plus“-Buskoppler für bis zu 64 Busklemmen (255 mit K-Bus-Verlängerung) | E16: EtherCAT “Economy plus“ Bus Coupler for up to 64 Bus Terminals (255 with K-bus extension) | F16: 49 | G16: -T- | H16: -T- | I16: -T- | J16: =COUNTIF(System_configuration!B:B,A16) -> 0
A17: BK1150 | B17: --- | C17: 2000 | D17: EtherCAT-„Compact“-Buskoppler für bis zu 64 Busklemmen (255 mit K-Bus-Verlängerung) | E17: EtherCAT “Compact“ Bus Coupler for up to 64 Bus Terminals (255 with K-bus extension) | F17: 44 | G17: -T- | H17: -T- | I17: -T- | J17: =COUNTIF(System_configuration!B:B,A17) -> 0
A18: BK1250 | B18: --- | C18: 500 | D18: EtherCAT-„Compact“-Koppler zwischen EtherCAT-Klemmen (E-Bus) und Busklemmen (K-Bus), Adapterklemme | E18: EtherCAT “Compact“ Coupler between EtherCAT Terminals (E-bus) and Bus Terminals (K-bus), adapter terminal | F18: 12 | G18: T | H18: T | I18: T | J18: =COUNTIF(System_configuration!B:B,A18) -> 0
A19: BK2000 | B19: --- | C19: 1750 | D19: Lightbus-Buskoppler für bis zu 64 Busklemmen | E19: Lightbus Bus Coupler for up to 64 Bus Terminals | F19: 49 | G19: -T- | H19: -T- | I19: -T- | J19: =COUNTIF(System_configuration!B:B,A19) -> 0
A20: BK2010 | B20: --- | C20: 500 | D20: Lightbus-Buskoppler für bis zu 64 digitale Busklemmen | E20: Lightbus Bus Coupler for up to 64 digital Bus Terminals | F20: 49 | G20: -T- | H20: -T- | I20: -T- | J20: =COUNTIF(System_configuration!B:B,A20) -> 0
A21: BK2020 | B21: --- | C21: 1750 | D21: Lightbus-„Economy plus“-Buskoppler für bis zu 64 Busklemmen (255 mit K-Bus-Verlängerung) | E21: Lightbus “Economy plus“ Bus Coupler for up to 64 Bus Terminals (255 with K-bus extension) | F21: 49 | G21: -T- | H21: -T- | I21: -T- | J21: =COUNTIF(System_configuration!B:B,A21) -> 0
A22: BK3010 | B22: --- | C22: 500 | D22: PROFIBUS-Buskoppler für bis zu 64 digitale Busklemmen, 1,5 MBaud | E22: PROFIBUS Bus Coupler for up to 64 digital Bus Terminals, 1.5 Mbaud | F22: 49 | G22: -T- | H22: -T- | I22: -T- | J22: =COUNTIF(System_configuration!B:B,A22) -> 0
A23: BK3100 | B23: --- | C23: 1750 | D23: PROFIBUS-DP/FMS-Buskoppler für bis zu 64 Busklemmen, 12 MBaud | E23: PROFIBUS DP/FMS Bus Coupler for up to 64 Bus Terminals, 12 Mbaud | F23: 49 | G23: -T- | H23: -T- | I23: -T- | J23: =COUNTIF(System_configuration!B:B,A23) -> 0
A24: BK3110 | B24: --- | C24: 500 | D24: PROFIBUS-Buskoppler für bis zu 64 digitale Busklemmen, 12 MBaud | E24: PROFIBUS Bus Coupler for up to 64 digital Bus Terminals, 12 Mbaud | F24: 49 | G24: -T- | H24: -T- | I24: -T- | J24: =COUNTIF(System_configuration!B:B,A24) -> 0
A25: BK3120 | B25: --- | C25: 1750 | D25: PROFIBUS-„Economy plus“-Buskoppler für bis zu 64 Busklemmen (255 mit K-Bus-Verlängerung), 12 MBaud | E25: PROFIBUS “Economy plus“ Bus Coupler for up to 64 Bus Terminals (255 with K-bus extension), 12 Mbaud | F25: 49 | G25: -T- | H25: -T- | I25: -T- | J25: =COUNTIF(System_configuration!B:B,A25) -> 0
A26: BK3150 | B26: --- | C26: 1000 | D26: PROFIBUS-„Compact“-Buskoppler für bis zu 64 Busklemmen (255 mit K-Bus-Verlängerung), 12 MBaud | E26: PROFIBUS “Compact“ Bus Coupler for up to 64 Bus Terminals (255 with K-bus extension), 12 Mbaud | F26: 44 | G26: -T- | H26: -T- | J26: =COUNTIF(System_configuration!B:B,A26) -> 0
A27: BK3520 | B27: --- | C27: 1750 | D27: PROFIBUS-„Economy plus“-Buskoppler mit LWL-Anschluss für bis zu 64 Busklemmen (255 mit K-Bus-Verlängerung), 12 MBaud | E27: PROFIBUS “Economy plus“ Bus Coupler with fibre optic connection for up to 64 Bus Terminals (255 with K-bus extension), 12 Mbaud | F27: 49 | G27: -T- | H27: -T- | I27: -T- | J27: =COUNTIF(System_configuration!B:B,A27) -> 0
A28: BK4000 | B28: --- | C28: 1750 | D28: Interbus-Buskoppler für bis zu 64 Busklemmen | E28: Interbus Bus Coupler for up to 64 Bus Terminals | F28: 49 | G28: -T- | H28: -T- | I28: -T- | J28: =COUNTIF(System_configuration!B:B,A28) -> 0
A29: BK4020 | B29: --- | C29: 1750 | D29: Interbus-„Economy plus“-Buskoppler für bis zu 64 Busklemmen (255 mit K-Bus-Verlängerung) | E29: Interbus “Economy plus“ Bus Coupler for up to 64 Bus Terminals (255 with K-bus extension) | F29: 49 | G29: -T- | H29: -T- | I29: -T- | J29: =COUNTIF(System_configuration!B:B,A29) -> 0
A30: BK5110 | B30: --- | C30: 500 | D30: CANopen-Buskoppler für bis zu 64 digitale Busklemmen | E30: CANopen Bus Coupler for up to 64 digital Bus Terminals | F30: 49 | G30: -T- | H30: -T- | I30: -T- | J30: =COUNTIF(System_configuration!B:B,A30) -> 0
A31: BK5120 | B31: --- | C31: 1750 | D31: CANopen-„Economy plus“-Buskoppler für bis zu 64 Busklemmen (255 mit K-Bus-Verlängerung) | E31: CANopen “Economy plus“ Bus Coupler for up to 64 Bus Terminals (255 with K-bus extension) | F31: 49 | G31: -T- | H31: -T- | I31: -T- | J31: =COUNTIF(System_configuration!B:B,A31) -> 0
A32: BK5150 | B32: --- | C32: 1000 | D32: CANopen-„Compact“-Buskoppler für bis zu 64 Busklemmen (255 mit K-Bus-Verlängerung) | E32: CANopen “Compact“ Bus Coupler for up to 64 Bus Terminals (255 with K-bus extension) | F32: 44 | G32: -T- | H32: -T- | J32: =COUNTIF(System_configuration!B:B,A32) -> 0
A33: BK5151 | B33: --- | C33: 1000 | D33: CANopen-„Compact“-Buskoppler für bis zu 64 Busklemmen (255 mit K-Bus-Verlängerung), Busanschluss: D-Sub-Stecker, 9-polig, anstatt Open-Style-Connector | E33: CANopen “Compact“ Bus Coupler for up to 64 Bus Terminals (255 with K-bus extension), Bus connection: D-sub plug, 9-pin instead of open style connector | F33: 44 | G33: -T- | H33: -T- | J33: =COUNTIF(System_configuration!B:B,A33) -> 0
A34: BK5200 | B34: --- | C34: 1750 | D34: DeviceNet-Buskoppler für bis zu 64 Busklemmen | E34: DeviceNet Bus Coupler for up to 64 Bus Terminals | F34: 49 | G34: -T- | H34: -T- | I34: -T- | J34: =COUNTIF(System_configuration!B:B,A34) -> 0
A35: BK5210 | B35: --- | C35: 500 | D35: DeviceNet-Buskoppler für bis zu 64 digitale Busklemmen | E35: DeviceNet Bus Coupler for up to 64 digital Bus Terminals | F35: 49 | G35: -T- | H35: -T- | I35: -T- | J35: =COUNTIF(System_configuration!B:B,A35) -> 0
A36: BK5220 | B36: --- | C36: 1750 | D36: DeviceNet-„Economy plus“-Buskoppler für bis zu 64 Busklemmen (255 mit K-Bus-Verlängerung) | E36: DeviceNet “Economy plus“ Bus Coupler for up to 64 Bus Terminals (255 with K-bus extension) | F36: 49 | G36: -T- | H36: -T- | I36: -T- | J36: =COUNTIF(System_configuration!B:B,A36) -> 0
A37: BK5250 | B37: --- | C37: 1000 | D37: DeviceNet-„Compact“-Buskoppler für bis zu 64 Busklemmen (255 mit K-Bus-Verlängerung) | E37: DeviceNet “Compact“ Bus Coupler for up to 64 Bus Terminals (255 with K-bus extension) | F37: 44 | G37: -T- | H37: -T- | J37: =COUNTIF(System_configuration!B:B,A37) -> 0
A38: BK7000 | B38: --- | C38: 1750 | D38: ControlNet-Buskoppler für bis zu 64 Busklemmen | E38: ControlNet Bus Coupler for up to 64 Bus Terminals | F38: 49 | G38: -T- | H38: -T- | I38: -T- | J38: =COUNTIF(System_configuration!B:B,A38) -> 0
A39: BK7150 | B39: --- | C39: 1000 | D39: CC-Link-„Compact“-Buskoppler für bis zu 64 Busklemmen (255 mit K-Bus-Verlängerung) | E39: CC-Link “Compact“ Bus Coupler for up to 64 Bus Terminals (255 with K-bus extension) | F39: 44 | G39: -T- | H39: -T- | J39: =COUNTIF(System_configuration!B:B,A39) -> 0
A40: BK7300 | B40: --- | C40: 1750 | D40: Modbus-Buskoppler für bis zu 64 Busklemmen | E40: Modbus Bus Coupler for up to 64 Bus Terminals | F40: 49 | G40: -T- | H40: -T- | I40: -T- | J40: =COUNTIF(System_configuration!B:B,A40) -> 0
...
